Il bot è connesso su discord
Ignoring exception in command shards:
Traceback (most recent call last):
  File "E:\Documents\Python\a71_discordbot\venv\lib\site-packages\discord\ext\commands\bot.py", line 903, in invoke
    await ctx.command.invoke(ctx)
  File "E:\Documents\Python\a71_discordbot\venv\lib\site-packages\discord\ext\commands\core.py", line 851, in invoke
    await self.prepare(ctx)
  File "E:\Documents\Python\a71_discordbot\venv\lib\site-packages\discord\ext\commands\core.py", line 786, in prepare
    await self._parse_arguments(ctx)
  File "E:\Documents\Python\a71_discordbot\venv\lib\site-packages\discord\ext\commands\core.py", line 697, in _parse_arguments
    transformed = await self.transform(ctx, param)
  File "E:\Documents\Python\a71_discordbot\venv\lib\site-packages\discord\ext\commands\core.py", line 542, in transform
    raise MissingRequiredArgument(param)
discord.ext.commands.errors.MissingRequiredArgument: what is a required argument that is missing.
